<mujoco model="diana">
    <compiler angle="radian" meshdir="meshes/combined/" />
    <size njmax="500" nconmax="100" />
    <asset>
        <mesh name="visual_base" file="visual_base.stl" />
        <mesh name="collision_base" file="collision_base.stl" />
        <mesh name="visual_link_1" file="visual_link_1.stl" />
        <mesh name="collision_link_1" file="collision_link_1.stl" />
        <mesh name="visual_link_2" file="visual_link_2.stl" />
        <mesh name="collision_link_2" file="collision_link_2.stl" />
        <mesh name="visual_link_3" file="visual_link_3.stl" />
        <mesh name="collision_link_3" file="collision_link_3.stl" />
        <mesh name="visual_link_4" file="visual_link_4.stl" />
        <mesh name="collision_link_4" file="collision_link_4.stl" />
        <mesh name="visual_link_5" file="visual_link_5.stl" />
        <mesh name="collision_link_5" file="collision_link_5.stl" />
        <mesh name="visual_link_6" file="visual_link_6.stl" />
        <mesh name="collision_link_6" file="collision_link_6.stl" />
        <mesh name="visual_link_7" file="visual_link_7.stl" />
        <mesh name="collision_link_7" file="collision_link_7.stl" />
    </asset>
    <worldbody>
        <geom type="mesh" contype="0" conaffinity="0" group="1" rgba="0.796078 0.823529 0.937255 1" mesh="visual_base" />
        <geom type="mesh" rgba="0.796078 0.823529 0.937255 1" mesh="collision_base" />
        <body name="link_1" pos="0 -1.17155e-10 0.2856" quat="2.05103e-10 -1 0 0">
            <inertial pos="5.52341e-05 -0.0254878 0.0355441" quat="0.691193 -0.148511 0.148051 0.691576" mass="1.09026" diaginertia="0.00692617 0.00585031 0.00412411" />
            <joint name="joint_1" pos="0 0 0" axis="0 0 1" limited="true" range="-3.12 3.12" />
            <geom quat="2.05103e-10 1 0 0" type="mesh" contype="0" conaffinity="0" group="1" rgba="0.796078 0.823529 0.937255 1" mesh="visual_link_1" />
            <geom quat="2.05103e-10 1 0 0" type="mesh" rgba="0.796078 0.823529 0.937255 1" mesh="collision_link_1" />
            <body name="link_2" pos="0.000586257 -0.000147825 -1.92077e-08" quat="0.707058 0.707149 -0.00213463 0.00213435">
                <inertial pos="-3.62725e-06 -0.0292741 -0.0412808" quat="0.617151 0.34497 -0.344838 0.61742" mass="1.09515" diaginertia="0.00672265 0.00575818 0.00369374" />
                <joint name="joint_2" pos="0 0 0" axis="0 0 1" limited="true" range="-1.57 1.57" />
                <geom type="mesh" contype="0" conaffinity="0" group="1" rgba="0.980392 0.980392 0.470588 1" mesh="visual_link_2" />
                <geom type="mesh" rgba="0.980392 0.980392 0.470588 1" mesh="collision_link_2" />
                <body name="link_3" pos="-0.0002216 -0.458739 0.000122156" quat="0.70701 -0.707199 -0.00181834 -0.00181785">
                    <inertial pos="0.0114318 -0.0101708 0.151317" quat="0.0446203 -0.531181 0.840931 -0.0932258" mass="2.01687" diaginertia="0.0380442 0.0369189 0.00782814" />
                    <joint name="joint_3" pos="0 0 0" axis="0 0 1" limited="true" range="-3.12 3.12" />
                    <geom quat="2.05103e-10 1 0 0" type="mesh" contype="0" conaffinity="0" group="1" rgba="0.898039 0.917647 0.929412 1" mesh="visual_link_3" />
                    <geom quat="2.05103e-10 1 0 0" type="mesh" rgba="0.898039 0.917647 0.929412 1" mesh="collision_link_3" />
                    <body name="link_4" pos="0.0654135 5.96931e-05 -1.21612e-08" quat="0.707175 0.707031 -0.00218523 0.00218567">
                        <inertial pos="-0.0240716 -0.0235632 -0.0366858" quat="0.759875 0.103862 -0.465331 0.441894" mass="0.849743" diaginertia="0.00419973 0.00389504 0.00186162" />
                        <joint name="joint_4" pos="0 0 0" axis="0 0 1" limited="true" range="0 3.05" />
                        <geom type="mesh" contype="0" conaffinity="0" group="1" rgba="0.898039 0.917647 0.929412 1" mesh="visual_link_4" />
                        <geom type="mesh" rgba="0.898039 0.917647 0.929412 1" mesh="collision_link_4" />
                        <body name="link_5" pos="-0.0528266 -0.454957 0.000420229" quat="0.706779 -0.707432 0.00112093 0.0011199">
                            <inertial pos="-0.00867148 0.03835 0.188626" quat="0.0377876 -0.446674 0.884579 0.128743" mass="1.2058" diaginertia="0.0219771 0.0218397 0.00233919" />
                            <joint name="joint_5" pos="0 0 0" axis="0 0 1" limited="true" range="-3.12 3.12" />
                            <geom pos="0 0 -0.02162" quat="2.05103e-10 1 0 0" type="mesh" contype="0" conaffinity="0" group="1" rgba="0.898039 0.917647 0.929412 1" mesh="visual_link_5" />
                            <geom pos="0 0 -0.02162" quat="2.05103e-10 1 0 0" type="mesh" rgba="0.898039 0.917647 0.929412 1" mesh="collision_link_5" />
                            <body name="link_6" pos="-0.0121169 -0.000123154 1.9628e-08" quat="-0.00208286 0.00208319 -0.70716 -0.707047">
                                <inertial pos="0.0458972 0.0084858 -0.00782578" quat="0.6118 -0.0424626 0.771157 -0.170922" mass="0.847158" diaginertia="0.00444053 0.00440141 0.00272972" />
                                <joint name="joint_6" pos="0 0 0" axis="0 0 1" limited="true" range="-3.12 0.52" />
                                <geom quat="0 0 1 2.05103e-10" type="mesh" contype="0" conaffinity="0" group="1" rgba="0.980392 0.980392 0.470588 1" mesh="visual_link_6" />
                                <geom quat="0 0 1 2.05103e-10" type="mesh" rgba="0.980392 0.980392 0.470588 1" mesh="collision_link_6" />
                                <body name="link_7" pos="0.087218 -0.1169 0.000298607" quat="0.706203 -0.708009 0 0">
                                    <inertial pos="0.00117005 5.03192e-06 0.0151382" quat="0.499962 0.501129 -0.498877 0.500029" mass="0.233956" diaginertia="0.000240243 0.000142027 0.000134422" />
                                    <joint name="joint_7" pos="0 0 0" axis="0 0 1" limited="true" range="-3.12 3.12" />
                                    <geom type="mesh" contype="0" conaffinity="0" group="1" rgba="0.898039 0.917647 0.929412 1" mesh="visual_link_7" />
                                    <geom type="mesh" rgba="0.898039 0.917647 0.929412 1" mesh="collision_link_7" />

                                    <body name="tool0_link" pos="0 0 0" quat="1 0 0 0">
<!--                                    <body name="tool0_link" pos="0 0 0" quat="0 0 0.707 0.707">-->
<!--                                    <body name="tool0_link" pos="0 0 0" quat="0.706203 0.708009 0 0">-->
                                        <site name="attachment_site" pos="0 0 -0.02" quat="0 0 0 1"/>
                                        <site name="eef_site" pos="0 0 -0.05" quat="0 0 0 1"/>
<!--                                        <site name="eef_site" pos="0 0 0" quat="0 0 0 1"/>-->
                                    </body>
                                </body>
                            </body>
                        </body>
                    </body>
                </body>
            </body>
        </body>
    </worldbody>
</mujoco>