<?xml version="1.0" encoding="utf-8"?>
<robot
  name="diana">
<mujoco>
      <compiler 
      meshdir="meshes/combined" 
      balanceinertia="true" 
      discardvisual="false" />
</mujoco>
  <link name="base" xmlns:xacro="http://www.ros.org/wiki/xacro">
    <inertial>
      <origin
        xyz="0.00153097191906452 0.00152031034664837 0.0524230280849149"
        rpy="0 0 0" />
      <mass
        value="1.33110743457779" />
      <inertia
        ixx="0.00695879790529406"
        ixy="9.99328685258342E-05"
        ixz="7.99577031212481E-05"
        iyy="0.00695365531716522"
        iyz="7.90796997368543E-05"
        izz="0.00729823323321907" />
    </inertial>
    <visual>
      <origin
        xyz="0 0 0"
        rpy="0 0 0" />
      <geometry>
        <mesh
          filename="visual_base.stl" />
      </geometry>
      <material
        name="">
        <color
          rgba="0.796078431372549 0.823529411764706 0.937254901960784 1" />
      </material>
    </visual>
    <collision>
      <origin
        xyz="0 0 0"
        rpy="0 0 0" />
      <geometry>
        <mesh
          filename="collision_base.stl" />
      </geometry>
    </collision>
  </link>
  <link
    name="link_1">
    <inertial>
      <origin
        xyz="5.5234067920554E-05  -0.0254878204920178 0.0355441421264809"
        rpy="0 0 0" />
      <mass
        value="1.09025546409174" />
      <inertia
        ixx="0.00585031196428369"
        ixy="1.4630349447555E-07"
        ixz="1.35351687162397E-06"
        iyy="0.00645496952227061"
        iyz="-0.00104800484741808"
        izz="0.00459531291521244" />
    </inertial>
    <visual>
      <origin
        xyz="0 0 0"
        rpy="3.1415926531795866 0 0" />
      <geometry>
        <mesh
          filename="visual_link_1.stl" />
      </geometry>
      <material
        name="">
        <color
          rgba="0.796078431372549 0.823529411764706 0.937254901960784 1" />
      </material>
    </visual>
    <collision>
      <origin
        xyz="0 0 0"
        rpy="3.1415926531795866 0 0" />
      <geometry>
        <mesh
          filename="collision_link_1.stl" />
      </geometry>
    </collision>
  </link>
  <joint
    name="joint_1"
    type="revolute">
    <origin
      xyz="0.0 -1.1715507836795716e-10 0.2856"
      rpy="-3.1415926531795866 0.0 -0.0" />
    <parent
      link="base" />
    <child
      link="link_1" />
    <axis
      xyz="0 0 1" />
    <limit
      lower="-3.12"
      upper="3.12"
      effort="235"
      velocity="2.618" />
  </joint>
  <link
    name="link_2">
    <inertial>
      <origin
        xyz="-3.62724763868157E-06 -0.0292741005087307 -0.041280769252073"
        rpy="0 0 0" />
      <mass
        value="1.09515454908799" />
      <inertia
        ixx="0.00575817488413533"
        ixy="4.92454490330888E-07"
        ixz="-5.75758988171004E-07"
        iyy="0.00452592941277235"
        iyz="0.00135206824645357"
        izz="0.0058904584276842" />
    </inertial>
    <visual>
      <origin
        xyz="0 0 0"
        rpy="0 0 0" />
      <geometry>
        <mesh
          filename="visual_link_2.stl" />
      </geometry>
      <material
        name="">
        <color
          rgba="0.980392156862745 0.980392156862745 0.470588235294118 1" />
      </material>
    </visual>
    <collision>
      <origin
        xyz="0 0 0"
        rpy="0 0 0" />
      <geometry>
        <mesh
          filename="collision_link_2.stl" />
      </geometry>
    </collision>
  </link>
  <joint
    name="joint_2"
    type="revolute">
    <origin
      xyz="0.0005862573385 -0.00014782485495212482 -1.9207652955671537e-08"
      rpy="1.57092626436801 -0.006037262313035355 -7.844624521808898e-07" />
    <parent
      link="link_1" />
    <child
      link="link_2" />
    <axis
      xyz="0 0 1" />
    <limit
      lower="-1.57"
      upper="1.57"
      effort="235"
      velocity="2.618" />
  </joint>
  <link
    name="link_3">
    <inertial>
      <origin
        xyz="0.0114318213510691 -0.0101707598694861 0.15131695375217"
        rpy="0 3.1415926531795866 3.1415926531795866" />
      <mass
        value="2.01686690128149" />
      <inertia
        ixx="0.0362470020041464"
        ixy="-0.00099203786071914"
        ixz="-0.00494440140493448"
        iyy="0.0374857206758098"
        iyz="-0.00313859974095155"
        izz="0.00905850119342719" />
    </inertial>
    <visual>
      <origin
        xyz="0 0 0"
        rpy="3.1415926531795866 0 0" />
      <geometry>
        <mesh
          filename="visual_link_3.stl" />
      </geometry>
      <material
        name="">
        <color
          rgba="0.898039215686275 0.917647058823529 0.929411764705882 1" />
      </material>
    </visual>
    <collision>
      <origin
        xyz="0 0 0"
        rpy="3.1415926531795866 0 0" />
      <geometry>
        <mesh
          filename="collision_link_3.stl" />
      </geometry>
    </collision>
  </link>
  <joint
    name="joint_3"
    type="revolute">
    <origin
      xyz="-0.000221599674 -0.45873900013566615 0.00012215632910532866"
      rpy="-1.5710626175208562 -0.005142349645679273 1.369354017489328e-06" />
    <parent
      link="link_2" />
    <child
      link="link_3" />
    <axis
      xyz="0 0 1" />
    <limit
      lower="-3.12"
      upper="3.12"
      effort="111"
      velocity="3.1416" />
  </joint>
  <link
    name="link_4">
    <inertial>
      <origin
        xyz="-0.0240716370537192 -0.0235631728011761 -0.0366858174253844"
        rpy="0 0 0" />
      <mass
        value="0.849743349506889" />
      <inertia
        ixx="0.00313444335639628"
        ixy="-0.000681243351041131"
        ixz="0.000725380047812207"
        iyy="0.00333717642442852"
        iyz="0.000771057559109157"
        izz="0.0034847726349841" />
    </inertial>
    <visual>
      <origin
        xyz="0 0 0"
        rpy="0 0 0" />
      <geometry>
        <mesh
          filename="visual_link_4.stl" />
      </geometry>
      <material
        name="">
        <color
          rgba="0.898039215686275 0.917647058823529 0.929411764705882 1" />
      </material>
    </visual>
    <collision>
      <origin
        xyz="0 0 0"
        rpy="0 0 0" />
      <geometry>
        <mesh
          filename="collision_link_4.stl" />
      </geometry>
    </collision>
  </link>
  <joint
    name="joint_4"
    type="revolute">
    <origin
      xyz="0.06541350239 5.969309933120634e-05 -1.2161203358645746e-08"
      rpy="1.5705925941077288 -0.006181400405717547 1.2593453126349397e-06" />
    <parent
      link="link_3" />
    <child
      link="link_4" />
    <axis
      xyz="0 0 1" />
    <limit
      lower="0"
      upper="3.05"
      effort="111"
      velocity="3.1416" />
  </joint>
  <link
    name="link_5">
    <inertial>
      <origin
        xyz="-0.00867148011164554 0.0383499684802812 0.188626"
        rpy="0 3.1415926531795866 3.1415926531795866" />
      <mass
        value="1.20580396965245" />
      <inertia
        ixx="0.0218436427570802"
        ixy="-0.000309747330693722"
        ixz="0.00089039094846826"
        iyy="0.0205896836785318"
        iyz="0.00493573923914426"
        izz="0.00372270106038425" />
    </inertial>
    <visual>
      <origin
        xyz="0 0 -0.02162"
        rpy="3.1415926531795866 0 0" />
      <geometry>
        <mesh
          filename="visual_link_5.stl" />
      </geometry>
      <material
        name="">
        <color
          rgba="0.898039215686275 0.917647058823529 0.929411764705882 1" />
      </material>
    </visual>
    <collision>
      <origin
        xyz="0 0 -0.02162"
        rpy="3.1415926531795866 0 0" />
      <geometry>
        <mesh
          filename="collision_link_5.stl" />
      </geometry>
    </collision>
  </link>
  <joint
    name="joint_5"
    type="revolute">
    <origin
      xyz="-0.05282664836 -0.45495749602433105 0.0004202289833435953"
      rpy="-1.5717199976380511 0.0031690147691578493 -2.927122476880115e-06" />
    <parent
      link="link_4" />
    <child
      link="link_5" />
    <axis
      xyz="0 0 1" />
    <limit
      lower="-3.12"
      upper="3.12"
      effort="54"
      velocity="2.618" />
  </joint>
  <link
    name="link_6">
    <inertial>
      <origin
        xyz="0.045897226241036 0.00848579821002571 -0.0078257811617596"
        rpy="0 3.1415926531795866 3.1415926531795866" />
      <mass
        value="0.847157564562275" />
      <inertia
        ixx="0.00286926864109097"
        ixy="-0.000341664135091818"
        ixz="-0.000318082297486923"
        iyy="0.0043294660443987"
        iyz="-5.82962380662208E-05"
        izz="0.00437292566725527" />
    </inertial>
    <visual>
      <origin
        xyz="0 0 0"
        rpy="3.1415926531795866 0 3.14159265359" />
      <geometry>
        <mesh
          filename="visual_link_6.stl" />
      </geometry>
      <material
        name="">
        <color
          rgba="0.980392156862745 0.980392156862745 0.470588235294118 1" />
      </material>
    </visual>
    <collision>
      <origin
        xyz="0 0 0"
        rpy="3.1415926531795866 0 3.14159265359" />
      <geometry>
        <mesh
          filename="collision_link_6.stl" />
      </geometry>
    </collision>
  </link>
  <joint
    name="joint_6"
    type="revolute">
    <origin
      xyz="-0.01211691155 -0.0001231537401358605 1.9628022220819176e-08"
      rpy="1.5709557077662104 0.005891691514963694 -3.1415917145717014" />
    <parent
      link="link_5" />
    <child
      link="link_6" />
    <axis
      xyz="0 0 1" />
    <limit
      lower="-3.12"
      upper="0.52"
      effort="54"
      velocity="2.618" />
  </joint>
  <link
    name="link_7">
    <inertial>
      <origin
        xyz="0.00117005127509708 5.03191940906655E-06 0.0151381784822231"
        rpy="0 0 0" />
      <mass
        value="0.233956150459573" />
      <inertia
        ixx="0.000142027360977168"
        ixy="1.76426389345981E-08"
        ixz="2.14635741626268E-07"
        iyy="0.000134421724783865"
        iyz="-1.29988689037464E-09"
        izz="0.000240242798572463" />
    </inertial>
    <visual>
      <origin
        xyz="0 0 0"
        rpy="0 0 0" />
      <geometry>
        <mesh
          filename="visual_link_7.stl" />
      </geometry>
      <material
        name="">
        <color
          rgba="0.898039215686275 0.917647058823529 0.929411764705882 1" />
      </material>
    </visual>
    <collision>
      <origin
        xyz="0 0 0"
        rpy="0 0 0" />
      <geometry>
        <mesh
          filename="collision_link_7.stl" />
      </geometry>
    </collision>
  </link>
  <joint
    name="joint_7"
    type="revolute">
    <origin
      xyz="0.08721799276 -0.11689961862134787 0.00029860707194743184"
      rpy="-1.57335071 0.0 -0.0" />
    <parent
      link="link_6" />
    <child
      link="link_7" />
    <axis
      xyz="0 0 1" />
    <limit
      lower="-3.12"
      upper="3.12"
      effort="54"
      velocity="3.1416" />
  </joint>
</robot>
